[2023-10-25T10:44:08.988+0000] {taskinstance.py:1159} INFO - Dependencies all met for dep_context=non-requeueable deps ti=<TaskInstance: ETL.Data_Transformation manual__2023-10-25T10:44:07.929838+00:00 [queued]>
[2023-10-25T10:44:08.995+0000] {taskinstance.py:1159} INFO - Dependencies all met for dep_context=requeueable deps ti=<TaskInstance: ETL.Data_Transformation manual__2023-10-25T10:44:07.929838+00:00 [queued]>
[2023-10-25T10:44:08.995+0000] {taskinstance.py:1361} INFO - Starting attempt 1 of 1
[2023-10-25T10:44:09.006+0000] {taskinstance.py:1382} INFO - Executing <Task(PythonOperator): Data_Transformation> on 2023-10-25 10:44:07.929838+00:00
[2023-10-25T10:44:09.012+0000] {standard_task_runner.py:57} INFO - Started process 188 to run task
[2023-10-25T10:44:09.016+0000] {standard_task_runner.py:84} INFO - Running: ['***', 'tasks', 'run', 'ETL', 'Data_Transformation', 'manual__2023-10-25T10:44:07.929838+00:00', '--job-id', '96', '--raw', '--subdir', 'DAGS_FOLDER/first_dags.py', '--cfg-path', '/tmp/tmp_fujz04l']
[2023-10-25T10:44:09.018+0000] {standard_task_runner.py:85} INFO - Job 96: Subtask Data_Transformation
[2023-10-25T10:44:09.056+0000] {task_command.py:416} INFO - Running <TaskInstance: ETL.Data_Transformation manual__2023-10-25T10:44:07.929838+00:00 [running]> on host 43405c62f061
[2023-10-25T10:44:09.149+0000] {taskinstance.py:1662} INFO - Exporting env vars: AIRFLOW_CTX_DAG_OWNER='me' AIRFLOW_CTX_DAG_ID='ETL' AIRFLOW_CTX_TASK_ID='Data_Transformation' AIRFLOW_CTX_EXECUTION_DATE='2023-10-25T10:44:07.929838+00:00' AIRFLOW_CTX_TRY_NUMBER='1' AIRFLOW_CTX_DAG_RUN_ID='manual__2023-10-25T10:44:07.929838+00:00'
[2023-10-25T10:44:09.258+0000] {taskinstance.py:1937} ERROR - Task failed with exception
Traceback (most recent call last):
  File "/home/airflow/.local/lib/python3.8/site-packages/airflow/operators/python.py", line 192, in execute
    return_value = self.execute_callable()
  File "/home/airflow/.local/lib/python3.8/site-packages/airflow/operators/python.py", line 209, in execute_callable
    return self.python_callable(*self.op_args, **self.op_kwargs)
  File "/opt/airflow/dags/first_dags.py", line 21, in data_transform
    df = fungsi.data_transform_func()
  File "/opt/airflow/dags/fungsi.py", line 19, in data_transform_func
    df.to_csv('/opt/airflow/data_csv/tangerang_transformed.csv', index = False)
  File "/home/airflow/.local/lib/python3.8/site-packages/pandas/core/generic.py", line 3772, in to_csv
    return DataFrameRenderer(formatter).to_csv(
  File "/home/airflow/.local/lib/python3.8/site-packages/pandas/io/formats/format.py", line 1186, in to_csv
    csv_formatter.save()
  File "/home/airflow/.local/lib/python3.8/site-packages/pandas/io/formats/csvs.py", line 240, in save
    with get_handle(
  File "/home/airflow/.local/lib/python3.8/site-packages/pandas/io/common.py", line 859, in get_handle
    handle = open(
PermissionError: [Errno 13] Permission denied: '/opt/airflow/data_csv/tangerang_transformed.csv'
[2023-10-25T10:44:09.266+0000] {taskinstance.py:1400} INFO - Marking task as FAILED. dag_id=ETL, task_id=Data_Transformation, execution_date=20231025T104407, start_date=20231025T104408, end_date=20231025T104409
[2023-10-25T10:44:09.277+0000] {standard_task_runner.py:104} ERROR - Failed to execute job 96 for task Data_Transformation ([Errno 13] Permission denied: '/opt/airflow/data_csv/tangerang_transformed.csv'; 188)
[2023-10-25T10:44:09.308+0000] {local_task_job_runner.py:228} INFO - Task exited with return code 1
[2023-10-25T10:44:09.323+0000] {taskinstance.py:2778} INFO - 0 downstream tasks scheduled from follow-on schedule check
