[2023-10-27T08:48:25.040+0000] {taskinstance.py:1159} INFO - Dependencies all met for dep_context=non-requeueable deps ti=<TaskInstance: ETL.generate_evidently_report manual__2023-10-27T08:48:22.715736+00:00 [queued]>
[2023-10-27T08:48:25.051+0000] {taskinstance.py:1159} INFO - Dependencies all met for dep_context=requeueable deps ti=<TaskInstance: ETL.generate_evidently_report manual__2023-10-27T08:48:22.715736+00:00 [queued]>
[2023-10-27T08:48:25.052+0000] {taskinstance.py:1361} INFO - Starting attempt 1 of 1
[2023-10-27T08:48:25.072+0000] {taskinstance.py:1382} INFO - Executing <Task(SSHOperator): generate_evidently_report> on 2023-10-27 08:48:22.715736+00:00
[2023-10-27T08:48:25.084+0000] {standard_task_runner.py:57} INFO - Started process 224 to run task
[2023-10-27T08:48:25.088+0000] {standard_task_runner.py:84} INFO - Running: ['***', 'tasks', 'run', 'ETL', 'generate_evidently_report', 'manual__2023-10-27T08:48:22.715736+00:00', '--job-id', '183', '--raw', '--subdir', 'DAGS_FOLDER/first_dags.py', '--cfg-path', '/tmp/tmptt8iqj7k']
[2023-10-27T08:48:25.092+0000] {standard_task_runner.py:85} INFO - Job 183: Subtask generate_evidently_report
[2023-10-27T08:48:25.150+0000] {task_command.py:416} INFO - Running <TaskInstance: ETL.generate_evidently_report manual__2023-10-27T08:48:22.715736+00:00 [running]> on host 45cd7075ee11
[2023-10-27T08:48:25.268+0000] {taskinstance.py:1662} INFO - Exporting env vars: AIRFLOW_CTX_DAG_OWNER='me' AIRFLOW_CTX_DAG_ID='ETL' AIRFLOW_CTX_TASK_ID='generate_evidently_report' AIRFLOW_CTX_EXECUTION_DATE='2023-10-27T08:48:22.715736+00:00' AIRFLOW_CTX_TRY_NUMBER='1' AIRFLOW_CTX_DAG_RUN_ID='manual__2023-10-27T08:48:22.715736+00:00'
[2023-10-27T08:48:25.270+0000] {ssh.py:135} INFO - Creating ssh_client
[2023-10-27T08:48:25.484+0000] {ssh.py:112} INFO - ssh_hook is not provided or invalid. Trying ssh_conn_id to create SSHHook.
[2023-10-27T08:48:25.497+0000] {base.py:73} INFO - Using connection ID 'host_machine' for task execution.
[2023-10-27T08:48:25.499+0000] {ssh.py:300} WARNING - No Host Key Verification. This won't protect against Man-In-The-Middle attacks
[2023-10-27T08:48:25.527+0000] {transport.py:1893} INFO - Connected (version 2.0, client OpenSSH_8.9p1)
[2023-10-27T08:48:25.691+0000] {transport.py:1893} INFO - Authentication (password) successful!
[2023-10-27T08:48:25.692+0000] {ssh.py:476} INFO - Running command: cd /home/***/data_science/power_bi && . .venv/bin/activate && python3 evidently.ai/generate_report.py && deactivate 
[2023-10-27T08:48:28.066+0000] {ssh.py:527} WARNING - Traceback (most recent call last):
[2023-10-27T08:48:28.066+0000] {ssh.py:527} WARNING -   File "/home/***/data_science/power_bi/evidently.ai/generate_report.py", line 19, in <module>
[2023-10-27T08:48:28.066+0000] {ssh.py:527} WARNING -     model = joblib.load('xgb.pkl')
[2023-10-27T08:48:28.066+0000] {ssh.py:527} WARNING -   File "/home/***/data_science/power_bi/.venv/lib/python3.10/site-packages/joblib/numpy_pickle.py", line 650, in load
[2023-10-27T08:48:28.066+0000] {ssh.py:527} WARNING -     with open(filename, 'rb') as f:
[2023-10-27T08:48:28.066+0000] {ssh.py:527} WARNING - FileNotFoundError: [Errno 2] No such file or directory: 'xgb.pkl'
[2023-10-27T08:48:28.528+0000] {taskinstance.py:1937} ERROR - Task failed with exception
Traceback (most recent call last):
  File "/home/airflow/.local/lib/python3.8/site-packages/airflow/providers/ssh/operators/ssh.py", line 173, in execute
    result = self.run_ssh_client_command(ssh_client, self.command, context=context)
  File "/home/airflow/.local/lib/python3.8/site-packages/airflow/providers/ssh/operators/ssh.py", line 161, in run_ssh_client_command
    self.raise_for_status(exit_status, agg_stderr, context=context)
  File "/home/airflow/.local/lib/python3.8/site-packages/airflow/providers/ssh/operators/ssh.py", line 154, in raise_for_status
    raise AirflowException(f"SSH operator error: exit status = {exit_status}")
airflow.exceptions.AirflowException: SSH operator error: exit status = 1
[2023-10-27T08:48:28.530+0000] {taskinstance.py:1400} INFO - Marking task as FAILED. dag_id=ETL, task_id=generate_evidently_report, execution_date=20231027T084822, start_date=20231027T084825, end_date=20231027T084828
[2023-10-27T08:48:28.543+0000] {standard_task_runner.py:104} ERROR - Failed to execute job 183 for task generate_evidently_report (SSH operator error: exit status = 1; 224)
[2023-10-27T08:48:28.581+0000] {local_task_job_runner.py:228} INFO - Task exited with return code 1
[2023-10-27T08:48:28.597+0000] {taskinstance.py:2778} INFO - 0 downstream tasks scheduled from follow-on schedule check
