[2023-10-22T12:24:08.166+0000] {taskinstance.py:1159} INFO - Dependencies all met for dep_context=non-requeueable deps ti=<TaskInstance: ETL.Upload_Data manual__2023-10-22T12:24:07.014439+00:00 [queued]>
[2023-10-22T12:24:08.176+0000] {taskinstance.py:1159} INFO - Dependencies all met for dep_context=requeueable deps ti=<TaskInstance: ETL.Upload_Data manual__2023-10-22T12:24:07.014439+00:00 [queued]>
[2023-10-22T12:24:08.176+0000] {taskinstance.py:1361} INFO - Starting attempt 1 of 1
[2023-10-22T12:24:08.202+0000] {taskinstance.py:1382} INFO - Executing <Task(PostgresOperator): Upload_Data> on 2023-10-22 12:24:07.014439+00:00
[2023-10-22T12:24:08.215+0000] {standard_task_runner.py:57} INFO - Started process 1527 to run task
[2023-10-22T12:24:08.221+0000] {standard_task_runner.py:84} INFO - Running: ['***', 'tasks', 'run', 'ETL', 'Upload_Data', 'manual__2023-10-22T12:24:07.014439+00:00', '--job-id', '18', '--raw', '--subdir', 'DAGS_FOLDER/first_dags.py', '--cfg-path', '/tmp/tmpemvgdrgx']
[2023-10-22T12:24:08.225+0000] {standard_task_runner.py:85} INFO - Job 18: Subtask Upload_Data
[2023-10-22T12:24:08.292+0000] {task_command.py:416} INFO - Running <TaskInstance: ETL.Upload_Data manual__2023-10-22T12:24:07.014439+00:00 [running]> on host dcd154787c99
[2023-10-22T12:24:08.461+0000] {taskinstance.py:1662} INFO - Exporting env vars: AIRFLOW_CTX_DAG_OWNER='me' AIRFLOW_CTX_DAG_ID='ETL' AIRFLOW_CTX_TASK_ID='Upload_Data' AIRFLOW_CTX_EXECUTION_DATE='2023-10-22T12:24:07.014439+00:00' AIRFLOW_CTX_TRY_NUMBER='1' AIRFLOW_CTX_DAG_RUN_ID='manual__2023-10-22T12:24:07.014439+00:00'
[2023-10-22T12:24:08.464+0000] {sql.py:274} INFO - Executing: 
        SELECT current_database;

        
[2023-10-22T12:24:08.478+0000] {base.py:73} INFO - Using connection ID 'postgres_docker' for task execution.
[2023-10-22T12:24:08.490+0000] {base.py:73} INFO - Using connection ID 'postgres_docker' for task execution.
[2023-10-22T12:24:08.502+0000] {sql.py:418} INFO - Running statement: 
        SELECT current_database;

        , parameters: None
[2023-10-22T12:24:08.505+0000] {taskinstance.py:1937} ERROR - Task failed with exception
Traceback (most recent call last):
  File "/home/airflow/.local/lib/python3.8/site-packages/airflow/providers/common/sql/operators/sql.py", line 280, in execute
    output = hook.run(
  File "/home/airflow/.local/lib/python3.8/site-packages/airflow/providers/common/sql/hooks/sql.py", line 392, in run
    self._run_command(cur, sql_statement, parameters)
  File "/home/airflow/.local/lib/python3.8/site-packages/airflow/providers/common/sql/hooks/sql.py", line 423, in _run_command
    cur.execute(sql_statement)
psycopg2.errors.UndefinedColumn: column "current_database" does not exist
LINE 2:         SELECT current_database;
                       ^

[2023-10-22T12:24:08.517+0000] {taskinstance.py:1400} INFO - Marking task as FAILED. dag_id=ETL, task_id=Upload_Data, execution_date=20231022T122407, start_date=20231022T122408, end_date=20231022T122408
[2023-10-22T12:24:08.545+0000] {standard_task_runner.py:104} ERROR - Failed to execute job 18 for task Upload_Data (column "current_database" does not exist
LINE 2:         SELECT current_database;
                       ^
; 1527)
[2023-10-22T12:24:08.557+0000] {local_task_job_runner.py:228} INFO - Task exited with return code 1
[2023-10-22T12:24:08.577+0000] {taskinstance.py:2778} INFO - 0 downstream tasks scheduled from follow-on schedule check
