[2023-10-25T10:51:54.370+0000] {taskinstance.py:1159} INFO - Dependencies all met for dep_context=non-requeueable deps ti=<TaskInstance: ETL.Data_Transformation manual__2023-10-25T10:51:53.466266+00:00 [queued]>
[2023-10-25T10:51:54.379+0000] {taskinstance.py:1159} INFO - Dependencies all met for dep_context=requeueable deps ti=<TaskInstance: ETL.Data_Transformation manual__2023-10-25T10:51:53.466266+00:00 [queued]>
[2023-10-25T10:51:54.380+0000] {taskinstance.py:1361} INFO - Starting attempt 1 of 1
[2023-10-25T10:51:54.394+0000] {taskinstance.py:1382} INFO - Executing <Task(PythonOperator): Data_Transformation> on 2023-10-25 10:51:53.466266+00:00
[2023-10-25T10:51:54.399+0000] {standard_task_runner.py:57} INFO - Started process 201 to run task
[2023-10-25T10:51:54.403+0000] {standard_task_runner.py:84} INFO - Running: ['***', 'tasks', 'run', 'ETL', 'Data_Transformation', 'manual__2023-10-25T10:51:53.466266+00:00', '--job-id', '104', '--raw', '--subdir', 'DAGS_FOLDER/first_dags.py', '--cfg-path', '/tmp/tmpbtx06mjj']
[2023-10-25T10:51:54.406+0000] {standard_task_runner.py:85} INFO - Job 104: Subtask Data_Transformation
[2023-10-25T10:51:54.447+0000] {task_command.py:416} INFO - Running <TaskInstance: ETL.Data_Transformation manual__2023-10-25T10:51:53.466266+00:00 [running]> on host d44eaeb05dd0
[2023-10-25T10:51:54.532+0000] {taskinstance.py:1662} INFO - Exporting env vars: AIRFLOW_CTX_DAG_OWNER='me' AIRFLOW_CTX_DAG_ID='ETL' AIRFLOW_CTX_TASK_ID='Data_Transformation' AIRFLOW_CTX_EXECUTION_DATE='2023-10-25T10:51:53.466266+00:00' AIRFLOW_CTX_TRY_NUMBER='1' AIRFLOW_CTX_DAG_RUN_ID='manual__2023-10-25T10:51:53.466266+00:00'
[2023-10-25T10:51:54.644+0000] {taskinstance.py:1937} ERROR - Task failed with exception
Traceback (most recent call last):
  File "/home/airflow/.local/lib/python3.8/site-packages/airflow/operators/python.py", line 192, in execute
    return_value = self.execute_callable()
  File "/home/airflow/.local/lib/python3.8/site-packages/airflow/operators/python.py", line 209, in execute_callable
    return self.python_callable(*self.op_args, **self.op_kwargs)
  File "/opt/airflow/dags/first_dags.py", line 21, in data_transform
    df = fungsi.data_transform_func()
  File "/opt/airflow/dags/fungsi.py", line 19, in data_transform_func
    df.to_csv('/opt/airflow/data_csv/tangerang_transformed.csv', index = False)
  File "/home/airflow/.local/lib/python3.8/site-packages/pandas/core/generic.py", line 3772, in to_csv
    return DataFrameRenderer(formatter).to_csv(
  File "/home/airflow/.local/lib/python3.8/site-packages/pandas/io/formats/format.py", line 1186, in to_csv
    csv_formatter.save()
  File "/home/airflow/.local/lib/python3.8/site-packages/pandas/io/formats/csvs.py", line 240, in save
    with get_handle(
  File "/home/airflow/.local/lib/python3.8/site-packages/pandas/io/common.py", line 859, in get_handle
    handle = open(
PermissionError: [Errno 13] Permission denied: '/opt/airflow/data_csv/tangerang_transformed.csv'
[2023-10-25T10:51:54.652+0000] {taskinstance.py:1400} INFO - Marking task as FAILED. dag_id=ETL, task_id=Data_Transformation, execution_date=20231025T105153, start_date=20231025T105154, end_date=20231025T105154
[2023-10-25T10:51:54.663+0000] {standard_task_runner.py:104} ERROR - Failed to execute job 104 for task Data_Transformation ([Errno 13] Permission denied: '/opt/airflow/data_csv/tangerang_transformed.csv'; 201)
[2023-10-25T10:51:54.698+0000] {local_task_job_runner.py:228} INFO - Task exited with return code 1
[2023-10-25T10:51:54.713+0000] {taskinstance.py:2778} INFO - 0 downstream tasks scheduled from follow-on schedule check
