[2023-10-25T10:38:28.055+0000] {taskinstance.py:1159} INFO - Dependencies all met for dep_context=non-requeueable deps ti=<TaskInstance: ETL.Data_Transformation manual__2023-10-25T10:38:27.298734+00:00 [queued]>
[2023-10-25T10:38:28.064+0000] {taskinstance.py:1159} INFO - Dependencies all met for dep_context=requeueable deps ti=<TaskInstance: ETL.Data_Transformation manual__2023-10-25T10:38:27.298734+00:00 [queued]>
[2023-10-25T10:38:28.065+0000] {taskinstance.py:1361} INFO - Starting attempt 1 of 1
[2023-10-25T10:38:28.080+0000] {taskinstance.py:1382} INFO - Executing <Task(PythonOperator): Data_Transformation> on 2023-10-25 10:38:27.298734+00:00
[2023-10-25T10:38:28.086+0000] {standard_task_runner.py:57} INFO - Started process 341 to run task
[2023-10-25T10:38:28.089+0000] {standard_task_runner.py:84} INFO - Running: ['***', 'tasks', 'run', 'ETL', 'Data_Transformation', 'manual__2023-10-25T10:38:27.298734+00:00', '--job-id', '92', '--raw', '--subdir', 'DAGS_FOLDER/first_dags.py', '--cfg-path', '/tmp/tmp37fdsr3i']
[2023-10-25T10:38:28.091+0000] {standard_task_runner.py:85} INFO - Job 92: Subtask Data_Transformation
[2023-10-25T10:38:28.140+0000] {task_command.py:416} INFO - Running <TaskInstance: ETL.Data_Transformation manual__2023-10-25T10:38:27.298734+00:00 [running]> on host ef9626e41a87
[2023-10-25T10:38:28.233+0000] {taskinstance.py:1662} INFO - Exporting env vars: AIRFLOW_CTX_DAG_OWNER='me' AIRFLOW_CTX_DAG_ID='ETL' AIRFLOW_CTX_TASK_ID='Data_Transformation' AIRFLOW_CTX_EXECUTION_DATE='2023-10-25T10:38:27.298734+00:00' AIRFLOW_CTX_TRY_NUMBER='1' AIRFLOW_CTX_DAG_RUN_ID='manual__2023-10-25T10:38:27.298734+00:00'
[2023-10-25T10:38:28.392+0000] {taskinstance.py:1937} ERROR - Task failed with exception
Traceback (most recent call last):
  File "/home/airflow/.local/lib/python3.8/site-packages/airflow/operators/python.py", line 192, in execute
    return_value = self.execute_callable()
  File "/home/airflow/.local/lib/python3.8/site-packages/airflow/operators/python.py", line 209, in execute_callable
    return self.python_callable(*self.op_args, **self.op_kwargs)
  File "/opt/airflow/dags/fungsi.py", line 19, in data_transform
    df.to_csv('/opt/airflow/data_csv/tangerang_transformed.csv', index = False)
  File "/home/airflow/.local/lib/python3.8/site-packages/pandas/core/generic.py", line 3772, in to_csv
    return DataFrameRenderer(formatter).to_csv(
  File "/home/airflow/.local/lib/python3.8/site-packages/pandas/io/formats/format.py", line 1186, in to_csv
    csv_formatter.save()
  File "/home/airflow/.local/lib/python3.8/site-packages/pandas/io/formats/csvs.py", line 240, in save
    with get_handle(
  File "/home/airflow/.local/lib/python3.8/site-packages/pandas/io/common.py", line 859, in get_handle
    handle = open(
PermissionError: [Errno 13] Permission denied: '/opt/airflow/data_csv/tangerang_transformed.csv'
[2023-10-25T10:38:28.406+0000] {taskinstance.py:1400} INFO - Marking task as FAILED. dag_id=ETL, task_id=Data_Transformation, execution_date=20231025T103827, start_date=20231025T103828, end_date=20231025T103828
[2023-10-25T10:38:28.421+0000] {standard_task_runner.py:104} ERROR - Failed to execute job 92 for task Data_Transformation ([Errno 13] Permission denied: '/opt/airflow/data_csv/tangerang_transformed.csv'; 341)
[2023-10-25T10:38:28.462+0000] {local_task_job_runner.py:228} INFO - Task exited with return code 1
[2023-10-25T10:38:28.483+0000] {taskinstance.py:2778} INFO - 0 downstream tasks scheduled from follow-on schedule check
