[2023-10-22T13:05:48.810+0000] {taskinstance.py:1159} INFO - Dependencies all met for dep_context=non-requeueable deps ti=<TaskInstance: ETL.Upload_Data manual__2023-10-22T13:05:47.918231+00:00 [queued]>
[2023-10-22T13:05:48.817+0000] {taskinstance.py:1159} INFO - Dependencies all met for dep_context=requeueable deps ti=<TaskInstance: ETL.Upload_Data manual__2023-10-22T13:05:47.918231+00:00 [queued]>
[2023-10-22T13:05:48.817+0000] {taskinstance.py:1361} INFO - Starting attempt 1 of 1
[2023-10-22T13:05:48.833+0000] {taskinstance.py:1382} INFO - Executing <Task(PostgresOperator): Upload_Data> on 2023-10-22 13:05:47.918231+00:00
[2023-10-22T13:05:48.840+0000] {standard_task_runner.py:57} INFO - Started process 1087 to run task
[2023-10-22T13:05:48.843+0000] {standard_task_runner.py:84} INFO - Running: ['***', 'tasks', 'run', 'ETL', 'Upload_Data', 'manual__2023-10-22T13:05:47.918231+00:00', '--job-id', '25', '--raw', '--subdir', 'DAGS_FOLDER/first_dags.py', '--cfg-path', '/tmp/tmpsjd9dg_a']
[2023-10-22T13:05:48.845+0000] {standard_task_runner.py:85} INFO - Job 25: Subtask Upload_Data
[2023-10-22T13:05:48.883+0000] {task_command.py:416} INFO - Running <TaskInstance: ETL.Upload_Data manual__2023-10-22T13:05:47.918231+00:00 [running]> on host 460880db6b82
[2023-10-22T13:05:48.953+0000] {taskinstance.py:1662} INFO - Exporting env vars: AIRFLOW_CTX_DAG_OWNER='me' AIRFLOW_CTX_DAG_ID='ETL' AIRFLOW_CTX_TASK_ID='Upload_Data' AIRFLOW_CTX_EXECUTION_DATE='2023-10-22T13:05:47.918231+00:00' AIRFLOW_CTX_TRY_NUMBER='1' AIRFLOW_CTX_DAG_RUN_ID='manual__2023-10-22T13:05:47.918231+00:00'
[2023-10-22T13:05:48.954+0000] {sql.py:274} INFO - Executing: 
        SELECT current_database();

        
[2023-10-22T13:05:48.962+0000] {base.py:73} INFO - Using connection ID 'postgres_docker' for task execution.
[2023-10-22T13:05:48.969+0000] {base.py:73} INFO - Using connection ID 'postgres_docker' for task execution.
[2023-10-22T13:05:48.978+0000] {taskinstance.py:1937} ERROR - Task failed with exception
Traceback (most recent call last):
  File "/home/airflow/.local/lib/python3.8/site-packages/airflow/providers/common/sql/operators/sql.py", line 280, in execute
    output = hook.run(
  File "/home/airflow/.local/lib/python3.8/site-packages/airflow/providers/common/sql/hooks/sql.py", line 385, in run
    with closing(self.get_conn()) as conn:
  File "/home/airflow/.local/lib/python3.8/site-packages/airflow/providers/postgres/hooks/postgres.py", line 155, in get_conn
    self.conn = psycopg2.connect(**conn_args)
  File "/home/airflow/.local/lib/python3.8/site-packages/psycopg2/__init__.py", line 122, in connect
    conn = _connect(dsn, connection_factory=connection_factory, **kwasync)
psycopg2.OperationalError: connection to server at "host.docker.internal" (192.168.65.254), port 5432 failed: FATAL:  database "db_scrapped2" does not exist

[2023-10-22T13:05:48.985+0000] {taskinstance.py:1400} INFO - Marking task as FAILED. dag_id=ETL, task_id=Upload_Data, execution_date=20231022T130547, start_date=20231022T130548, end_date=20231022T130548
[2023-10-22T13:05:48.996+0000] {standard_task_runner.py:104} ERROR - Failed to execute job 25 for task Upload_Data (connection to server at "host.docker.internal" (192.168.65.254), port 5432 failed: FATAL:  database "db_scrapped2" does not exist
; 1087)
[2023-10-22T13:05:49.015+0000] {local_task_job_runner.py:228} INFO - Task exited with return code 1
[2023-10-22T13:05:49.030+0000] {taskinstance.py:2778} INFO - 0 downstream tasks scheduled from follow-on schedule check
