[2023-10-22T03:47:19.577+0000] {taskinstance.py:1159} INFO - Dependencies all met for dep_context=non-requeueable deps ti=<TaskInstance: first_dagg.task1 manual__2023-10-22T03:47:18.897827+00:00 [queued]>
[2023-10-22T03:47:19.585+0000] {taskinstance.py:1159} INFO - Dependencies all met for dep_context=requeueable deps ti=<TaskInstance: first_dagg.task1 manual__2023-10-22T03:47:18.897827+00:00 [queued]>
[2023-10-22T03:47:19.585+0000] {taskinstance.py:1361} INFO - Starting attempt 1 of 1
[2023-10-22T03:47:19.600+0000] {taskinstance.py:1382} INFO - Executing <Task(SSHOperator): task1> on 2023-10-22 03:47:18.897827+00:00
[2023-10-22T03:47:19.605+0000] {standard_task_runner.py:57} INFO - Started process 2002 to run task
[2023-10-22T03:47:19.608+0000] {standard_task_runner.py:84} INFO - Running: ['***', 'tasks', 'run', 'first_dagg', 'task1', 'manual__2023-10-22T03:47:18.897827+00:00', '--job-id', '10', '--raw', '--subdir', 'DAGS_FOLDER/first_dags.py', '--cfg-path', '/tmp/tmpe6cy5xl2']
[2023-10-22T03:47:19.611+0000] {standard_task_runner.py:85} INFO - Job 10: Subtask task1
[2023-10-22T03:47:19.647+0000] {task_command.py:416} INFO - Running <TaskInstance: first_dagg.task1 manual__2023-10-22T03:47:18.897827+00:00 [running]> on host 60e772682c42
[2023-10-22T03:47:19.714+0000] {taskinstance.py:1662} INFO - Exporting env vars: AIRFLOW_CTX_DAG_OWNER='me' AIRFLOW_CTX_DAG_ID='first_dagg' AIRFLOW_CTX_TASK_ID='task1' AIRFLOW_CTX_EXECUTION_DATE='2023-10-22T03:47:18.897827+00:00' AIRFLOW_CTX_TRY_NUMBER='1' AIRFLOW_CTX_DAG_RUN_ID='manual__2023-10-22T03:47:18.897827+00:00'
[2023-10-22T03:47:19.715+0000] {ssh.py:135} INFO - Creating ssh_client
[2023-10-22T03:47:19.747+0000] {ssh.py:112} INFO - ssh_hook is not provided or invalid. Trying ssh_conn_id to create SSHHook.
[2023-10-22T03:47:19.755+0000] {base.py:73} INFO - Using connection ID 'host_machine' for task execution.
[2023-10-22T03:47:19.756+0000] {ssh.py:300} WARNING - No Host Key Verification. This won't protect against Man-In-The-Middle attacks
[2023-10-22T03:47:19.756+0000] {ssh.py:342} INFO - Failed to connect. Sleeping before retry attempt 1
[2023-10-22T03:47:24.642+0000] {ssh.py:342} INFO - Failed to connect. Sleeping before retry attempt 2
[2023-10-22T03:47:28.991+0000] {taskinstance.py:1937} ERROR - Task failed with exception
Traceback (most recent call last):
  File "/home/airflow/.local/lib/python3.8/site-packages/airflow/providers/ssh/operators/ssh.py", line 172, in execute
    with self.get_ssh_client() as ssh_client:
  File "/home/airflow/.local/lib/python3.8/site-packages/airflow/providers/ssh/operators/ssh.py", line 136, in get_ssh_client
    return self.get_hook().get_conn()
  File "/home/airflow/.local/lib/python3.8/site-packages/airflow/providers/ssh/hooks/ssh.py", line 346, in get_conn
    for attempt in Retrying(
  File "/home/airflow/.local/lib/python3.8/site-packages/tenacity/__init__.py", line 347, in __iter__
    do = self.iter(retry_state=retry_state)
  File "/home/airflow/.local/lib/python3.8/site-packages/tenacity/__init__.py", line 325, in iter
    raise retry_exc.reraise()
  File "/home/airflow/.local/lib/python3.8/site-packages/tenacity/__init__.py", line 158, in reraise
    raise self.last_attempt.result()
  File "/usr/local/lib/python3.8/concurrent/futures/_base.py", line 437, in result
    return self.__get_result()
  File "/usr/local/lib/python3.8/concurrent/futures/_base.py", line 389, in __get_result
    raise self._exception
  File "/home/airflow/.local/lib/python3.8/site-packages/airflow/providers/ssh/hooks/ssh.py", line 353, in get_conn
    client.connect(**connect_kwargs)
  File "/home/airflow/.local/lib/python3.8/site-packages/paramiko/client.py", line 377, in connect
    to_try = list(self._families_and_addresses(hostname, port))
  File "/home/airflow/.local/lib/python3.8/site-packages/paramiko/client.py", line 202, in _families_and_addresses
    addrinfos = socket.getaddrinfo(
  File "/usr/local/lib/python3.8/socket.py", line 918, in getaddrinfo
    for res in _socket.getaddrinfo(host, port, family, type, proto, flags):
socket.gaierror: [Errno -2] Name or service not known
[2023-10-22T03:47:29.000+0000] {taskinstance.py:1400} INFO - Marking task as FAILED. dag_id=first_dagg, task_id=task1, execution_date=20231022T034718, start_date=20231022T034719, end_date=20231022T034728
[2023-10-22T03:47:29.010+0000] {standard_task_runner.py:104} ERROR - Failed to execute job 10 for task task1 ([Errno -2] Name or service not known; 2002)
[2023-10-22T03:47:29.044+0000] {local_task_job_runner.py:228} INFO - Task exited with return code 1
[2023-10-22T03:47:29.059+0000] {taskinstance.py:2778} INFO - 0 downstream tasks scheduled from follow-on schedule check
